<mujoco model="Maze">
    <compiler inertiafromgeom="true" angle="radian"/>

    <visual>
        <scale framelength="0.5" framewidth="0.05"/>
    </visual>

    <option timestep="0.01"/>;

    <asset>
        <mesh name="mesh:agent" file="agent.stl"/>
        <texture name="tex:floor" type="2d" builtin="checker" rgb1="1 1 1" rgb2="0 0 0" width="100" height="100"
                 mark="cross"/>
        <material name="mat:floor" reflectance="0.1" texture="tex:floor" texrepeat="14 14"/>
    </asset>

    <default>
        <joint armature="1" damping="1"/>
        <geom contype="1" condim="3" friction="1 0.1 0.1"/>

        <default class="slider-x">
            <joint type="slide" axis="1 0 0"/>
        </default>

        <default class="slider-y">
            <joint type="slide" axis="0 1 0"/>
        </default>

        <default class="obstacle">
            <geom type="box" size="3 0.5 2" rgba="0 0 1 1"/>
        </default>

        <default class="agent">
            <geom type="mesh" mesh="mesh:agent"/>
        </default>

        <default class="wall-inner">
            <geom type="box" size="5 0.5 2" rgba="0 1 0 1"/>
        </default>

        <default class="wall-x">
            <geom type="box" size="15 0.5 2" quat="1 0 1 0" rgba="0 1 0 1"/>
        </default>

        <default class="wall-y">
            <geom type="box" size="0.5 14 2" quat="1 0 1 0" rgba="0 1 0 1"/>
        </default>
    </default>

    <worldbody>
        <light name="light" directional="true" diffuse="0.8 0.8 0.8" specular="0.4 0.4 0.4" pos="0 -10 20"
               dir="0 1 -1"/>
        <geom name="floor" type="plane" material="mat:floor" size="14 14 1" pos="0 0 0" rgba="0.752 0.752 0.752 1"
              quat="1 0 0 0"/>

        <body name="agent" pos="2 -11 0.01">
            <joint name="slider:agent-x" class="slider-x"/>
            <joint name="slider:agent-y" class="slider-y"/>
            <geom name="agent" rgba="1 0 0 1" class="agent" mass="1"/>
        </body>

        <body name="obstacle" pos="0 0 2">
            <joint name="slider:obstacle" class="slider-x"/>
            <geom name="obstacle" class="obstacle" mass="1"/>
        </body>

        <body name="goal" pos="-9 11 0.005">
            <site type="box" size="5 3 0.01" rgba="128 0 128 0.2"/>
        </body>

        <body name="wall:inner0" pos="-9 7.5 2">
            <geom name="wall:inner0" class="wall-inner"/>
        </body>

        <body name="wall:inner1" pos="9 -7.5 2">
            <geom name="wall:inner1" class="wall-inner"/>
        </body>

        <body name="wall:south" pos="0 -14.5 2" quat="1 0 1 0">
            <geom name="wall:south" class="wall-x"/>
        </body>

        <body name="wall:north" pos="0 14.5 2" quat="1 0 1 0">
            <geom name="wall:north" class="wall-x"/>
        </body>

        <body name="wall:west" pos="-14.5 0 2" quat="1 0 1 0">
            <geom name="wall:west" class="wall-y"/>
        </body>

        <body name="wall:east" pos="14.5 0 2" quat="1 0 1 0">
            <geom name="wall:east" class="wall-y"/>
        </body>
    </worldbody>

    <actuator>
        <velocity name="slider:obstacle" joint="slider:obstacle"/>
        <velocity name="slider:agent-x" joint="slider:agent-x"/>
        <velocity name="slider:agent-y" joint="slider:agent-y"/>
    </actuator>
</mujoco>
